<?xml version="1.0" encoding="utf-8" standalone="yes"?><rss version="2.0" xmlns:atom="http://www.w3.org/2005/Atom"><channel><title>line on HANDMADE LOG</title><link>https://handmade.iptime.org/tags/line/</link><description>Recent content in line on HANDMADE LOG</description><generator>Hugo -- gohugo.io</generator><language>en-us</language><copyright>This work is licensed under a Creative Commons Attribution-NonCommercial 4.0 International License.</copyright><lastBuildDate>Tue, 04 Aug 2020 15:29:30 +0900</lastBuildDate><atom:link href="https://handmade.iptime.org/tags/line/index.xml" rel="self" type="application/rss+xml"/><item><title>Show code of exception occurred when call exec on python</title><link>https://handmade.iptime.org/posts/2020-08-04-show_code_of_exception_occurred_when_call_exec_on_python/</link><pubDate>Tue, 04 Aug 2020 15:29:30 +0900</pubDate><guid>https://handmade.iptime.org/posts/2020-08-04-show_code_of_exception_occurred_when_call_exec_on_python/</guid><description>python 에서 exec 함수를 통해 임의의 코드를 수행시킬때, 예외가 발생했다면, 예외가 발생한 부분을 정확히 알고 싶을때 어떻게 할 수 있을까요@.@? 다음과 같이 traceback 을 서식화</description></item></channel></rss>